Workbook

Sheet Artikelauswertung
A1: Inventur zum 31.12.2024
A3: Nr | B3: Beschreibung | C3: Beschreibung 2 | D3: Produktgruppencode | E3: Inventurgruppencode | F3: Lagerort | G3: Bestand Datum | H3: Basiseinheit | I3: Nettogewicht kg/ Einheit | J3: Nettogewicht kg | K3: Bewertungspreis € / Einheit | L3: Bewertungspreis €
A4: H063 | B4: Europaletten | D4: 807 | E4: Fertigwaren | F4: HAUPT | G4: 35911 | H4: STÜCK | I4: 20 | J4: =G4*I4 -> 718220 | K4: 7.67 | L4: =G4*K4 -> 275437.37
A5: 81222012 | B5: Lilys Kitchen Dog Chicken & Duck | C5: Countryside Casserole Adult Dry Food - Indu | D5: 510 | E5: Fertigwaren | F5: HAUPT | G5: 18316 | H5: STÜCK | I5: 12 | J5: =G5*I5 -> 219792 | K5: 17.7922 | L5: =G5*K5 -> 325881.94
A6: 5462012 | B6: Canagan Free-Range Chicken For Dogs | D6: 510 | E6: Fertigwaren | F6: HAUPT | G6: 15392 | H6: STÜCK | I6: 12 | J6: =G6*I6 -> 184704 | K6: 14.4104 | L6: =G6*K6 -> 221804.88
A7: 8005125 | B7: Wolfsblut Wild Duck Adult | D7: 510 | E7: Fertigwaren | F7: HAUPT | G7: 11052 | H7: STÜCK | I7: 12.5 | J7: =G7*I7 -> 138150 | K7: 16.532 | L7: =G7*K7 -> 182711.66
A8: 81212012 | B8: Lilys Kitchen Dog Lamb | C8: Shepherds Pie Adult Dry Food - Indu | D8: 510 | E8: Fertigwaren | F8: HAUPT | G8: 7258 | H8: STÜCK | I8: 12 | J8: =G8*I8 -> 87096 | K8: 22.7752 | L8: =G8*K8 -> 165302.4
A9: 5735012 | B9: Canagan Grass Fed Lamb For Dogs | D9: 510 | E9: Fertigwaren | F9: HAUPT | G9: 5728 | H9: STÜCK | I9: 12 | J9: =G9*I9 -> 68736 | K9: 28.3642 | L9: =G9*K9 -> 162470.14
A10: 8004125 | B10: Wolfsblut Adult Wide Plain Horse | D10: 510 | E10: Fertigwaren | F10: HAUPT | G10: 4927 | H10: STÜCK | I10: 12.5 | J10: =G10*I10 -> 61587.5 | K10: 29.6931 | L10: =G10*K10 -> 146297.9
A11: 8338012 | B11: Sanabelle Adult Geflügel | D11: 503 | E11: Fertigwaren | F11: HAUPT | G11: 7455 | H11: STÜCK | I11: 12 | J11: =G11*I11 -> 89460 | K11: 16.9252 | L11: =G11*K11 -> 126177.37
A12: 53120012 | B12: Briantos Prive Soft Adult Lachs & Kartoffel LA | D12: 510 | E12: Fertigwaren | F12: HAUPT | G12: 9790 | H12: STÜCK | I12: 12 | J12: =G12*I12 -> 117480 | K12: 12.7742 | L12: =G12*K12 -> 125059.42
A13: 8053125 | B13: Wolfsblut Dark Forest Adult | D13: 510 | E13: Fertigwaren | F13: HAUPT | G13: 5952 | H13: STÜCK | I13: 12.5 | J13: =G13*I13 -> 74400 | K13: 20.8038 | L13: =G13*K13 -> 123824.22
A14: 81242012 | B14: Lilys Kitchen Dog Duck, Salmon & Venison | C14: Wild Woodland Walk Adult Dry Food - Indu | D14: 510 | E14: Fertigwaren | F14: HAUPT | G14: 6015 | H14: STÜCK | I14: 12 | J14: =G14*I14 -> 72180 | K14: 19.9562 | L14: =G14*K14 -> 120036.54
A15: 5472012 | B15: Canagan Scottish Salmon For Dogs | D15: 510 | E15: Fertigwaren | F15: HAUPT | G15: 5980 | H15: STÜCK | I15: 12 | J15: =G15*I15 -> 71760 | K15: 19.2522 | L15: =G15*K15 -> 115128.16
A16: 52010015 | B16: Junior Lamm & Reis | D16: 502 | E16: Fertigwaren | F16: HAUPT | G16: 7538 | H16: STÜCK | I16: 15 | J16: =G16*I16 -> 113070 | K16: 15.2069 | L16: =G16*K16 -> 114629.61
A17: 51963010 | B17: K-Classic Kroketten mit Rind & Gemüse | C17: Kaufland (OE) - Relaunch | D17: 510 | E17: Fertigwaren | F17: HAUPT | G17: 34964 | H17: STÜCK | I17: 10 | J17: =G17*I17 -> 349640 | K17: 3.2257 | L17: =G17*K17 -> 112783.37
A18: 56140012 | B18: Edgard & Cooper Dog Export Dry Lamb | D18: 510 | E18: Fertigwaren | F18: HAUPT | G18: 5171 | H18: STÜCK | I18: 12 | J18: =G18*I18 -> 62052 | K18: 21.3324 | L18: =G18*K18 -> 110309.84
A19: 51482012 | B19: Wildkind RED CANYON | D19: 510 | E19: Fertigwaren | F19: HAUPT | G19: 3720 | H19: STÜCK | I19: 12 | J19: =G19*I19 -> 44640 | K19: 26.3139 | L19: =G19*K19 -> 97887.708
A20: 52160125 | B20: Senior | D20: 502 | E20: Fertigwaren | F20: HAUPT | G20: 12311 | H20: STÜCK | I20: 12.5 | J20: =G20*I20 -> 153887.5 | K20: 7.8355 | L20: =G20*K20 -> 96462.84
A21: 57570125 | B21: HPC SOFT Maxi Wasserbüffel & Süßkartoffel | D21: 519 | E21: Fertigwaren | F21: HAUPT | G21: 3920 | H21: STÜCK | I21: 12.5 | J21: =G21*I21 -> 49000 | K21: 24.593 | L21: =G21*K21 -> 96404.56
A22: 548614 | B22: Tales u Tails Soft Ente & Gemüse | D22: 510 | E22: Fertigwaren | F22: BRUCKER_2 | G22: 14832 | H22: STÜCK | I22: 4 | J22: =G22*I22 -> 59328 | K22: 6.4287 | L22: =G22*K22 -> 95350.478
A23: 5465012 | B23: Canagan Large Breed Free-Range Chicken For Dogs | D23: 510 | E23: Fertigwaren | F23: HAUPT | G23: 6576 | H23: STÜCK | I23: 12 | J23: =G23*I23 -> 78912 | K23: 14.3893 | L23: =G23*K23 -> 94624.037
A24: 5726012 | B24: Canagan Country Game For Dogs | D24: 510 | E24: Fertigwaren | F24: HAUPT | G24: 5300 | H24: STÜCK | I24: 12 | J24: =G24*I24 -> 63600 | K24: 17.2894 | L24: =G24*K24 -> 91633.82
A25: 5211 | B25: HPC Active Relaunch | C25: braunes mittelgroßes Viereck | D25: 853 | E25: Monokroketten | F25: HAUPT | G25: 100696.5 | H25: KG | I25: 1 | J25: =G25*I25 -> 100696.5 | K25: 0.5794 | L25: =G25*K25 -> 58343.552
A26: 5462006 | B26: Canagan Free-Range Chicken For Dogs | D26: 510 | E26: Fertigwaren | F26: HAUPT | G26: 12716 | H26: STÜCK | I26: 6 | J26: =G26*I26 -> 76296 | K26: 7.2052 | L26: =G26*K26 -> 91621.323
A27: 5466012 | B27: Canagan Light / Senior For Dogs | D27: 510 | E27: Fertigwaren | F27: HAUPT | G27: 6221 | H27: STÜCK | I27: 12 | J27: =G27*I27 -> 74652 | K27: 14.5728 | L27: =G27*K27 -> 90657.389
A28: 52080015 | B28: Adult Lamm & Reis | D28: 502 | E28: Fertigwaren | F28: HAUPT | G28: 9101 | H28: STÜCK | I28: 15 | J28: =G28*I28 -> 136515 | K28: 9.9609 | L28: =G28*K28 -> 90654.151
A29: 8124207 | B29: Lilys Kitchen Dog Duck, Salmon & Venison | C29: Wild Woodland Walk Adult Dry food - Indu | D29: 510 | E29: Fertigwaren | F29: HAUPT | G29: 7668 | H29: STÜCK | I29: 7 | J29: =G29*I29 -> 53676 | K29: 11.6722 | L29: =G29*K29 -> 89502.43
A30: 56150012 | B30: Edgard & Cooper Dog Export Dry Vension & Duck | D30: 510 | E30: Fertigwaren | F30: HAUPT | G30: 5032 | H30: STÜCK | I30: 12 | J30: =G30*I30 -> 60384 | K30: 16.7111 | L30: =G30*K30 -> 84090.255
A31: 850004 | B31: Tales u Tails Soft Pferd | D31: 510 | E31: Fertigwaren | F31: BRUCKER_2 | G31: 6048 | H31: STÜCK | I31: 4 | J31: =G31*I31 -> 24192 | K31: 13.7269 | L31: =G31*K31 -> 83020.291
A32: 57142015 | B32: Orlando Gourmet Hundetrockenfutter SK4 | C32: RO/HR/BG/GR,CY/RS | D32: 510 | E32: Fertigwaren | F32: HAUPT | G32: 101490 | H32: STÜCK | I32: 1.5 | J32: =G32*I32 -> 152235 | K32: 0.8171 | L32: =G32*K32 -> 82927.479
A33: 557714 | B33: Tales u Tails Soft Lamm | D33: 510 | E33: Fertigwaren | F33: BRUCKER_2 | G33: 6408 | H33: STÜCK | I33: 4 | J33: =G33*I33 -> 25632 | K33: 12.9014 | L33: =G33*K33 -> 82672.171
A34: 81212025 | B34: Lilys Kitchen Dog Lamb | C34: Shepherds Pie Adult Dry Food - Indu | D34: 510 | E34: Fertigwaren | F34: HAUPT | G34: 16064 | H34: STÜCK | I34: 2.5 | J34: =G34*I34 -> 40160 | K34: 5.0142 | L34: =G34*K34 -> 80548.109
A35: 83460010 | B35: Sanabelle Sterilized | D35: 503 | E35: Fertigwaren | F35: HAUPT | G35: 5685 | H35: STÜCK | I35: 10 | J35: =G35*I35 -> 56850 | K35: 14.1381 | L35: =G35*K35 -> 80375.098
A36: 5424107 | B36: HeyHoly Kleine Doggen | C36: Beautiful Bulldogs | D36: 510 | E36: Fertigwaren | F36: HAUPT | G36: 8710 | H36: STÜCK | I36: 7 | J36: =G36*I36 -> 60970 | K36: 9.1977 | L36: =G36*K36 -> 80111.967
A37: 8122201 | B37: Lilys Kitchen Dog Chicken & Duck | C37: Countryside Casserole Adult Dry Food - Indu | D37: 510 | E37: Fertigwaren | F37: HAUPT | G37: 45360 | H37: STÜCK | I37: 1 | J37: =G37*I37 -> 45360 | K37: 1.7129 | L37: =G37*K37 -> 77697.144
A38: 8336 | B38: Sanabelle Sensitiv Geflügel Relaunch 2018 | C38: Dunkelbraune kleine Scheibe | D38: 853 | E38: Monokroketten | F38: HAUPT | G38: 22908 | H38: KG | I38: 1 | J38: =G38*I38 -> 22908 | K38: 1.2424 | L38: =G38*K38 -> 28460.899
A39: 7979 | B39: Ex.Dog rotes geriffeltes Ei 4 % Rind 4 % Erbsen | C39: rotes großes geriffeltes Ei | D39: 851 | E39: Extrudate | F39: HAUPT | G39: 123115.94 | H39: KG | I39: 1 | J39: =G39*I39 -> 123115.94 | K39: 0.2396 | L39: =G39*K39 -> 29498.579
A40: 5233102 | B40: 4 Paws Softbrocken mit Huhn | D40: 510 | E40: Fertigwaren | F40: HAUPT | G40: 33696 | H40: STÜCK | I40: 2 | J40: =G40*I40 -> 67392 | K40: 2.3018 | L40: =G40*K40 -> 77561.453
A41: 53110012 | B41: Briantos Prive Soft Adult Ente & Kartoffel LA | D41: 510 | E41: Fertigwaren | F41: HAUPT | G41: 6749 | H41: STÜCK | I41: 12 | J41: =G41*I41 -> 80988 | K41: 11.2575 | L41: =G41*K41 -> 75976.868
...

Sheet Kategorien Summen
B2: 2024
A3: Zeilenbeschriftungen | B3: Summe von Nettogewicht kg | C3: Summe von Bewertungspreis € | D3: Summen
A4: Ersatzteile | B4: =SUMIF(Artikelauswertung!$E$4:$E$12118,'Kategorien Summen'!A4,Artikelauswertung!$J$4:$J$12118) -> 2043836.1 | C4: =SUMIF(Artikelauswertung!$E$4:$E$12118,'Kategorien Summen'!A4,Artikelauswertung!$L$4:$L$12118) -> 10079558 | D4: =C4 -> 10079558
A5: Extrudate | B5: =SUMIF(Artikelauswertung!$E$4:$E$12118,'Kategorien Summen'!A5,Artikelauswertung!$J$4:$J$12118) -> 1415461.1 | C5: =SUMIF(Artikelauswertung!$E$4:$E$12118,'Kategorien Summen'!A5,Artikelauswertung!$L$4:$L$12118) -> 1091260.8 | D5: bei Halbfabrikate
A6: Fertigwaren | B6: =SUMIF(Artikelauswertung!$E$4:$E$12118,'Kategorien Summen'!A6,Artikelauswertung!$J$4:$J$12118) -> 25271877 | C6: =SUMIF(Artikelauswertung!$E$4:$E$12118,'Kategorien Summen'!A6,Artikelauswertung!$L$4:$L$12118) -> 24934929 | D6: =C6*0.92 -> 22940135
A7: Halbfabrikate | B7: =SUMIF(Artikelauswertung!$E$4:$E$12118,'Kategorien Summen'!A7,Artikelauswertung!$J$4:$J$12118) -> 736720.51 | C7: =SUMIF(Artikelauswertung!$E$4:$E$12118,'Kategorien Summen'!A7,Artikelauswertung!$L$4:$L$12118) -> 545255.72 | D7: =C7+C5+C8 -> 3137857.7
A8: Monokroketten | B8: =SUMIF(Artikelauswertung!$E$4:$E$12118,'Kategorien Summen'!A8,Artikelauswertung!$J$4:$J$12118) -> 1946057.7 | C8: =SUMIF(Artikelauswertung!$E$4:$E$12118,'Kategorien Summen'!A8,Artikelauswertung!$L$4:$L$12118) -> 1501341.2 | D8: bei Halbfabrikate
A9: Rohstoffe | B9: =SUMIF(Artikelauswertung!$E$4:$E$12118,'Kategorien Summen'!A9,Artikelauswertung!$J$4:$J$12118) -> 14010401 | C9: =SUMIF(Artikelauswertung!$E$4:$E$12118,'Kategorien Summen'!A9,Artikelauswertung!$L$4:$L$12118) -> 15685651 | D9: =C9 -> 15685651
A10: Verpackungen | B10: =SUMIF(Artikelauswertung!$E$4:$E$12118,'Kategorien Summen'!A10,Artikelauswertung!$J$4:$J$12118) -> 3618866.7 | C10: =SUMIF(Artikelauswertung!$E$4:$E$12118,'Kategorien Summen'!A10,Artikelauswertung!$L$4:$L$12118) -> 16244287 | D10: =C10 -> 16244287
A11: Werbeartikel | B11: =SUMIF(Artikelauswertung!$E$4:$E$12118,'Kategorien Summen'!A11,Artikelauswertung!$J$4:$J$12118) -> 39733.893 | C11: =SUMIF(Artikelauswertung!$E$4:$E$12118,'Kategorien Summen'!A11,Artikelauswertung!$L$4:$L$12118) -> 539665.09 | D11: =C11 -> 539665.09
A12: Müll | B12: =SUMIF(Artikelauswertung!$E$4:$E$12118,'Kategorien Summen'!A12,Artikelauswertung!$J$4:$J$12118) -> 92670 | C12: =SUMIF(Artikelauswertung!$E$4:$E$12118,'Kategorien Summen'!A12,Artikelauswertung!$L$4:$L$12118) -> 11894.37 | D12: =C12 -> 11894.37 | F12: Kategorie gab es bisher nicht
A13: Gesamtergebnis | B13: =SUM(B4:B12) -> 49175624 | C13: =SUM(C4:C12) -> 70633842 | D13: =SUM(D4:D12) -> 68639048
A15: Anmerkung für 2024
A16: Bei der FW wurde Verpackungsschwund und Mischkosten, reduzierte Palettenpreise
A17: mit 8% in Abzug gebracht
A20: 2023 ist voraussichtlich nicht letzter Stand, wie gebucht. Die Zahlen müssten von Buchhaltung eingeholt werden und hier korrigiert werden.
B21: 2023
A22: Zeilenbeschriftungen | B22: Summe von Nettogewicht kg | C22: Summe von Bewertungspreis € | D22: Summen
A23: Ersatzteile | B23: 1047426.1 | C23: 271754.04 | D23: 271754.04 | F23: Zeile 2022 nicht vorhanden, 2021 vorhanden, aber mit 0 Euro
A24: Extrudate | B24: 1494408.2 | C24: 1231395.8 | D24: bei Halbfabrikate
A25: Fertigwaren | B25: 22347855 | C25: 21828709 | D25: 20082412
A26: Halbfabrikate | B26: 795656.88 | C26: 638660.71 | D26: 4085313.6
A27: Monokroketten | B27: 2448487.9 | C27: 2215257.1 | D27: bei Halbfabrikate
A28: Rohstoffe | B28: 9614552.6 | C28: 9583952.5 | D28: 9583952.5
A29: Verpackungen | B29: 3597567 | C29: 17512936 | D29: 17512936
A30: Werbeartikel | B30: 34182.173 | C30: 595012.96 | D30: 595012.96 | F30: Zeile 2022 nicht vorhanden, 2021 vorhanden, aber mit 0 Euro
A31: Gesamtergebnis | B31: 41380136 | C31: 53877678 | D31: 52131382
A33: Anmerkung für 2023
A34: Bei der FW wurde Verpackungsschwund und Mischkosten, reduzierte Palettenpreise | F34: Kann das wieder so angesetzt werden? Wir seit 2018 so angesetzt
A35: mit 8% in Abzug gebracht
A38: 2022
A39: Zeilenbeschriftungen | B39: Summe von Nettogewicht kg | C39: Summe von Bewertungspreis € | D39: Summen
A40: Extrudate | B40: 1433201.4 | C40: 891707.43 | D40: bei Halbfabrikate
A41: Fertigwaren | B41: 18064398 | C41: 19907182 | D41: =GETPIVOTDATA("Summe von Bewertungspreis €",$A$20,"Inventurgruppencode","Fertigwaren")*0.92 -> #REF!
A42: Halbfabrikate | B42: 439002.61 | C42: 277346.37 | D42: =GETPIVOTDATA("Summe von Bewertungspreis €",$A$20,"Inventurgruppencode","Halbfabrikate")+GETPIVOTDATA("Summe von Bewertungspreis €",$A$20,"Inventurgruppencode","Extrudate")+GETPIVOTDATA("Summe von Bewertungspreis €",$A$20,"Inventurgruppencode","Monokroketten") -> #REF!
A43: Monokroketten | B43: 1624891.2 | C43: 1176074.1 | D43: bei Halbfabrikate
A44: Rohstoffe | B44: 13146247 | C44: 11314141 | D44: =GETPIVOTDATA("Summe von Bewertungspreis €",$A$20,"Inventurgruppencode","Rohstoffe") -> #REF!
A45: Verpackungen | B45: 2740982.4 | C45: 15321361 | D45: =GETPIVOTDATA("Summe von Bewertungspreis €",$A$20,"Inventurgruppencode","Verpackungen") -> #REF!
A46: Gesamtergebnis | B46: 37448722 | C46: 48887811 | D46: =SUM(D40:D45) -> #REF!
A48: Anmerkung für 2022
...
