Workbook

Sheet Inventur_2023_Datensätze
A1: Auswertung zum 30.12.23
A2: Inventurauswertung per 30.12.2023
A4: Nr | B4: Beschreibung | C4: Beschreibung 2 | D4: Produktgruppencode | E4: Inventurgruppencode | F4: Bestand Datum | G4: Basiseinheit | H4: Nettogewicht kg/ Einheit | I4: Nettogewicht kg | J4: Bewertungspreis € / Einheit | K4: Bewertungspreis €
A5: 3000 | B5: Mehl 3000 Standard Geflügel | D5: 849 | E5: Halbfabrikate | F5: 1500 | G5: KG | H5: 1 | I5: =H5*F5 -> 1500 | J5: 0.3804 | K5: =F5*J5 -> 570.6
A6: 3024 | B6: T 3024 Mehl helle Farben | D6: 849 | E6: Halbfabrikate | F6: 0 | G6: KG | H6: 1 | I6: =H6*F6 -> 0 | J6: 0.3273 | K6: =F6*J6 -> 0
A7: 3042 | B7: VM Vorextrusion für 3056 | D7: 851 | E7: Extrudate | F7: 0 | G7: KG | H7: 1 | I7: =H7*F7 -> 0 | J7: 1.0197 | K7: =F7*J7 -> 0
A8: 3051 | B8: Vormischung Extrudiert für MM Gebackenes HF, Rind | D8: 849 | E8: Halbfabrikate | F8: 0 | G8: KG | H8: 1 | I8: =H8*F8 -> 0 | J8: 1.4696 | K8: =F8*J8 -> 0
A9: 3054 | B9: VM Dechra Treat Blend | C9: TEST | D9: 855 | E9: Extrudate | F9: 0 | G9: KG | H9: 1 | I9: =H9*F9 -> 0 | J9: 4.4492 | K9: =F9*J9 -> 0
A10: 3101 | B10: Vorextrusion für 3102 Mehl McAdams Award Snack | D10: 851 | E10: Extrudate | F10: 0 | G10: KG | H10: 1 | I10: =H10*F10 -> 0 | J10: 3.0395 | K10: =F10*J10 -> 0
A11: 3129 | B11: Mehl 3129 Geflügel | D11: 849 | E11: Halbfabrikate | F11: 10400 | G11: KG | H11: 1 | I11: =H11*F11 -> 10400 | J11: 0.3773 | K11: =F11*J11 -> 3923.92
A12: 3135 | B12: Mehl 3135 Geflügel Backlinie1 | D12: 849 | E12: Halbfabrikate | F12: 500 | G12: KG | H12: 1 | I12: =H12*F12 -> 500 | J12: 0.4666 | K12: =F12*J12 -> 233.3
A13: 5015 | B13: Premiere Adult Semi Moist | C13: braunes großes Stäbchen | D13: 853 | E13: Monokroketten | F13: 9400 | G13: KG | H13: 1 | I13: =H13*F13 -> 9400 | J13: 0.8176 | K13: =F13*J13 -> 7685.44
A14: 5017 | B14: Premiere Soft Junior Chicken | C14: braunes kleines Dreieck SOFT | D14: 853 | E14: Monokroketten | F14: 1400 | G14: KG | H14: 1 | I14: =H14*F14 -> 1400 | J14: 0.8957 | K14: =F14*J14 -> 1253.98
A15: 5026 | B15: BC Mini Frischfleisch | C15: brauner kleiner Zylinder | D15: 853 | E15: Monokroketten | F15: 1400 | G15: KG | H15: 1 | I15: =H15*F15 -> 1400 | J15: 1.1303 | K15: =F15*J15 -> 1582.42
A16: 5044 | B16: Buffo Single Ente No Grain | C16: braune mittelgroße Scheibe | D16: 853 | E16: Monokroketten | F16: 4500 | G16: KG | H16: 1 | I16: =H16*F16 -> 4500 | J16: 0.8159 | K16: =F16*J16 -> 3671.55
A17: 5045 | B17: Aldi High Premium NHMP | C17: braunes mittelgroßes Viereck | D17: 853 | E17: Monokroketten | F17: 4200 | G17: KG | H17: 1 | I17: =H17*F17 -> 4200 | J17: 0.5871 | K17: =F17*J17 -> 2465.82
A18: 5053 | B18: Katze HP Senior m. Frischfleisch | C18: hellbraune kleine Scheibe | D18: 853 | E18: Monokroketten | F18: 30892.012 | G18: KG | H18: 1 | I18: =H18*F18 -> 30892.012 | J18: 0.9382 | K18: =F18*J18 -> 28982.886
A19: 5054 | B19: Sanabelle Hairball-Snack Relaunch | C19: braune kleine Scheibe | D19: 853 | E19: Monokroketten | F19: 750 | G19: KG | H19: 1 | I19: =H19*F19 -> 750 | J19: 1.3891 | K19: =F19*J19 -> 1041.825
A20: 5056 | B20: Sanabelle Thanks-Snack Relaunch | C20: braunes mittelgroßes Herz | D20: 853 | E20: Monokroketten | F20: 10764.94 | G20: KG | H20: 1 | I20: =H20*F20 -> 10764.94 | J20: 1.3278 | K20: =F20*J20 -> 14293.687
A21: 5059 | B21: HPC soft Plus Ziege | C21: braunes großes Viereck SOFT | D21: 853 | E21: Monokroketten | F21: 32600 | G21: KG | H21: 1 | I21: =H21*F21 -> 32600 | J21: 1.3063 | K21: =F21*J21 -> 42585.38
A22: 5062 | B22: Briantos Adult Lachs & Reis | C22: braune große Scheibe | D22: 853 | E22: Monokroketten | F22: 0 | G22: KG | H22: 1 | I22: =H22*F22 -> 0 | J22: 0.6405 | K22: =F22*J22 -> 0
A23: 5067 | B23: Briantos Adult Maxi Huhn & Reis | C23: braune große Scheibe | D23: 853 | E23: Monokroketten | F23: 9139.721 | G23: KG | H23: 1 | I23: =H23*F23 -> 9139.721 | J23: 0.6422 | K23: =F23*J23 -> 5869.5288
A24: 5070 | B24: HPC Soft Hühnchen & Banane | C24: braunes großes Viereck SOFT | D24: 853 | E24: Monokroketten | F24: 0 | G24: KG | H24: 1 | I24: =H24*F24 -> 0 | J24: 0.7801 | K24: =F24*J24 -> 0
... A164: 6185 | B164: Pets at Home Dental Stick | C164: softer Dental Stick | D164: 848 | E164: Halbfabrikate | F164: 0 | G164: KG | H164: 1 | I164: =H164*F164 -> 0 | J164: 0.6918 | K164: =F164*J164 -> 0
A165: 6204 | B165: Cat Sticks Lachs & Forelle | D165: 848 | E165: Halbfabrikate | F165: 0 | G165: KG | H165: 1 | I165: =H165*F165 -> 0 | J165: 1.5515 | K165: =F165*J165 -> 0
A166: 6205 | B166: Dog Sticks Geflügel | C166: bräunlicher DogStick | D166: 848 | E166: Halbfabrikate | F166: 0 | G166: KG | H166: 1 | I166: =H166*F166 -> 0 | J166: 1.5862 | K166: =F166*J166 -> 0
A167: 6206 | B167: Dog Sticks Rind | C167: rötlicher Dog Stick | D167: 848 | E167: Halbfabrikate | F167: 0 | G167: KG | H167: 1 | I167: =H167*F167 -> 0 | J167: 2.135 | K167: =F167*J167 -> 0
A168: 6209 | B168: Dog Sticks Mercadona Chicken Liver | C168: Dog Stick | D168: 848 | E168: Halbfabrikate | F168: 0 | G168: KG | H168: 1 | I168: =H168*F168 -> 0 | J168: 1.7358 | K168: =F168*J168 -> 0
A169: 6210 | B169: Mercadona Dog Sticks Lachs mit Rote Beete | C169: Dog Stick | D169: 848 | E169: Halbfabrikate | F169: 0 | G169: KG | H169: 1 | I169: =H169*F169 -> 0 | J169: 1.5445 | K169: =F169*J169 -> 0
A170: 6211 | B170: Aldi Cat Sticks Lamm, Truthahn, Yucca, Taurin | D170: 848 | E170: Halbfabrikate | F170: 0 | G170: KG | H170: 1 | I170: =H170*F170 -> 0 | J170: 2.9061 | K170: =F170*J170 -> 0
A171: 6212 | B171: Aldi Cat Sticks Geflügel, Leber, Yucca, Taurin | D171: 848 | E171: Halbfabrikate | F171: 0 | G171: KG | H171: 1 | I171: =H171*F171 -> 0 | J171: 1.5601 | K171: =F171*J171 -> 0
A172: 6213 | B172: Aldi Cat Sticks Lachs, Forelle, Yucca, Taurin | D172: 848 | E172: Halbfabrikate | F172: 0 | G172: KG | H172: 1 | I172: =H172*F172 -> 0 | J172: 2.1176 | K172: =F172*J172 -> 0
A173: 6217 | B173: Sanabelle Snack Seelachs & Feige MSC | D173: 848 | E173: Halbfabrikate | F173: 0 | G173: KG | H173: 1 | I173: =H173*F173 -> 0 | J173: 1.9205 | K173: =F173*J173 -> 0
A174: 6225 | B174: fit+fun Sticks Kaninchen & Pute & Hefe | D174: 848 | E174: Halbfabrikate | F174: 0 | G174: KG | H174: 1 | I174: =H174*F174 -> 0 | J174: 1.6644 | K174: =F174*J174 -> 0
A175: 6242 | B175: Cat Stick kurz! Lamm, Katzenminze | D175: 848 | E175: Halbfabrikate | F175: 0 | G175: KG | H175: 1 | I175: =H175*F175 -> 0 | J175: 1.9055 | K175: =F175*J175 -> 0
A176: 6249 | B176: Dog Sticks Gen. II | C176: Brauner Dog Stick 12/13 mm | D176: 848 | E176: Halbfabrikate | F176: 0 | G176: KG | H176: 1 | I176: =H176*F176 -> 0 | J176: 1.7963 | K176: =F176*J176 -> 0
A177: 6255 | B177: Cat Sticks Quattrofahne Apfel | D177: 848 | E177: Halbfabrikate | F177: 0 | G177: KG | H177: 1 | I177: =H177*F177 -> 0 | J177: 1.4914 | K177: =F177*J177 -> 0
A178: 6256 | B178: Cat Sticks Quattrofahne Karotte | D178: 848 | E178: Halbfabrikate | F178: 0 | G178: KG | H178: 1 | I178: =H178*F178 -> 0 | J178: 1.6728 | K178: =F178*J178 -> 0
A179: 6257 | B179: Cat Sticks Quattrofahne Tomate | D179: 848 | E179: Halbfabrikate | F179: 0 | G179: KG | H179: 1 | I179: =H179*F179 -> 0 | J179: 2.28 | K179: =F179*J179 -> 0
A180: 6258 | B180: Cat Sticks Quattrofahnen Petersilie | C180: rotbraun normale Sticks | D180: 848 | E180: Halbfabrikate | F180: 0 | G180: KG | H180: 1 | I180: =H180*F180 -> 0 | J180: 2.2509 | K180: =F180*J180 -> 0
...

Sheet Inventur_2023_Kategorien
B2: 2023
A3: Zeilenbeschriftungen | B3: Summe von Nettogewicht kg | C3: Summe von Bewertungspreis € | D3: Summen
A4: Ersatzteile | B4: =SUMIF(Inventur_2023_Datensätze!$E$5:$E$10959,A4, Inventur_2023_Datensätze!$I$5:$I$10959) -> 107375.32 | C4: =SUMIF(Inventur_2023_Datensätze!$E$5:$E$10959, A4,Inventur_2023_Datensätze!$K$5:$K$10959) -> 389676.22 | D4: =C4 -> 389676.22 | F4: War früher extra Liste. Jetzt eine komplette Datei | I4: davon rein Ersatzteile | J4: 284694.58
A5: Extrudate | B5: =SUMIF(Inventur_2023_Datensätze!$E$5:$E$10959,A5, Inventur_2023_Datensätze!$I$5:$I$10959) -> 1494408.2 | C5: =SUMIF(Inventur_2023_Datensätze!$E$5:$E$10959, A5,Inventur_2023_Datensätze!$K$5:$K$10959) -> 1231395.8 | D5: bei Halbfabrikate | I5: davon nur Diesel | J5: 82704.28
A6: Fertigwaren | B6: =SUMIF(Inventur_2023_Datensätze!$E$5:$E$10959,A6, Inventur_2023_Datensätze!$I$5:$I$10959) -> 22344255 | C6: =SUMIF(Inventur_2023_Datensätze!$E$5:$E$10959, A6,Inventur_2023_Datensätze!$K$5:$K$10959) -> 21821297 | D6: =C6*0.92 -> 20075594 | I6: davon nur Heizöl | J6: 13032.6
A7: Halbfabrikate | B7: =SUMIF(Inventur_2023_Datensätze!$E$5:$E$10959,A7, Inventur_2023_Datensätze!$I$5:$I$10959) -> 795656.88 | C7: =SUMIF(Inventur_2023_Datensätze!$E$5:$E$10959, A7,Inventur_2023_Datensätze!$K$5:$K$10959) -> 638660.71 | D7: =C7+C5+C8 -> 3938188.7 | I7: davon nur Gas Propan | J7: 6195.7
A8: Monokroketten | B8: =SUMIF(Inventur_2023_Datensätze!$E$5:$E$10959,A8, Inventur_2023_Datensätze!$I$5:$I$10959) -> 2213486.9 | C8: =SUMIF(Inventur_2023_Datensätze!$E$5:$E$10959, A8,Inventur_2023_Datensätze!$K$5:$K$10959) -> 2068132.1 | D8: bei Halbfabrikate | I8: davon nur Gas Stapler | J8: 3049.06
A9: Rohstoffe | B9: =SUMIF(Inventur_2023_Datensätze!$E$5:$E$10959,A9, Inventur_2023_Datensätze!$I$5:$I$10959) -> 10087519 | C9: =SUMIF(Inventur_2023_Datensätze!$E$5:$E$10959, A9,Inventur_2023_Datensätze!$K$5:$K$10959) -> 9901043.8 | D9: =C9 -> 9901043.8 | I9: Summe: | J9: =SUM(J4:J8) -> 389676.22
A10: Verpackungen | B10: =SUMIF(Inventur_2023_Datensätze!$E$5:$E$10959,A10, Inventur_2023_Datensätze!$I$5:$I$10959) -> 3597567 | C10: =SUMIF(Inventur_2023_Datensätze!$E$5:$E$10959, A10,Inventur_2023_Datensätze!$K$5:$K$10959) -> 17512936 | D10: =C10 -> 17512936
A11: Werbeartikel | B11: =SUMIF(Inventur_2023_Datensätze!$E$5:$E$10959,A11, Inventur_2023_Datensätze!$I$5:$I$10959) -> 23766.36 | C11: =SUMIF(Inventur_2023_Datensätze!$E$5:$E$10959, A11,Inventur_2023_Datensätze!$K$5:$K$10959) -> 0 | D11: =C11 -> 0
A12: Gesamtergebnis | B12: =SUM(B4:B11) -> 40664035 | C12: =SUM(C4:C11) -> 53563142 | D12: =SUM(D4:D11) -> 51817438
A14: Anmerkung für 2023
A15: Bei der FW wurde Verpackungsschwund und Mischkosten, reduzierte Palettenpreise | F15: Kann das wieder so angesetzt werden? Wird seit 2018 so angesetzt .
A16: mit 8% in Abzug gebracht
A19: 2022
A20: Zeilenbeschriftungen | B20: Summe von Nettogewicht kg | C20: Summe von Bewertungspreis € | D20: Summen
A21: Extrudate | B21: 1433201.4 | C21: 891707.43 | D21: bei Halbfabrikate
A22: Fertigwaren | B22: 18064398 | C22: 19907182 | D22: =GETPIVOTDATA("Summe von Bewertungspreis €",$A$20,"Inventurgruppencode","Fertigwaren")*0.92 -> 18314607
A23: Halbfabrikate | B23: 439002.61 | C23: 277346.37 | D23: =GETPIVOTDATA("Summe von Bewertungspreis €",$A$20,"Inventurgruppencode","Halbfabrikate")+GETPIVOTDATA("Summe von Bewertungspreis €",$A$20,"Inventurgruppencode","Extrudate")+GETPIVOTDATA("Summe von Bewertungspreis €",$A$20,"Inventurgruppencode","Monokroketten") -> 2345127.9
A24: Monokroketten | B24: 1624891.2 | C24: 1176074.1 | D24: bei Halbfabrikate
A25: Rohstoffe | B25: 13146247 | C25: 11314141 | D25: =GETPIVOTDATA("Summe von Bewertungspreis €",$A$20,"Inventurgruppencode","Rohstoffe") -> 11314141
A26: Verpackungen | B26: 2740982.4 | C26: 15321361 | D26: =GETPIVOTDATA("Summe von Bewertungspreis €",$A$20,"Inventurgruppencode","Verpackungen") -> 15321361
A27: Gesamtergebnis | B27: 37448722 | C27: 48887811 | D27: =SUM(D21:D26) -> 47295237
A29: Anmerkung für 2022
A30: Bei der FW wurde Verpackungsschwund und Mischkosten, reduzierte Palettenpreise
A31: mit 8% in Abzug gebracht
A34: 2021 | E34: Vergleich zum VJ | G34: 2020 | K34: Vergleich zum VJ | M34: 2019 | O34: Vergleich zum VJ | Q34: 2018 | T34: 2017 | W34: 2016 | Z34: 2015
A35: Zeilenbeschriftungen | B35: Summe von Nettogewicht kg | C35: Summe von Bewertungspreis € | D35: Summen | G35: Zeilenbeschriftungen | H35: Summe von Nettogewicht | I35: Summe von Bewertungspreis | J35: Summen | M35: Ersatzteile/Motorenteile | N35: 0 | O35: 0 | Q35: Ersatzteile | R35: 0 | T35: Bezeichnung | U35: Summe von Bewertung | W35: Bezeichung | X35: Summe von Bewertung | Z35: Bezeichung | AA35: Summe von Bewertung
A36: Ersatzteile | B36: 9971 | C36: 0 | D36: 0 | G36: Ersatzteile | H36: 0 | I36: 0 | J36: 0 | M36: Fertigwaren | N36: 10706679 | O36: 0.0044 | Q36: Extrudate | R36: 823759.75 | T36: Fertigware | U36: 10195743 | W36: Roh- Hilfs- und Betriebsstoffe | X36: 12626612 | Z36: Roh- Hilfs- und Betriebsstoffe | AA36: 11472310
A37: Extrudate | B37: 1140508.2 | C37: 856739.16 | D37: bei Halbfabrikate | G37: Extrudate | H37: 810464.66 | I37: 672696.77 | J37: bei Halbfabrikate | M37: Halbfertigwaren | N37: 1677701.5 | O37: -0.024 | Q37: Fertigwaren | R37: 10660046 | T37: Unfertige Erzeugnisse | U37: 722932.57 | W37: unfertige Erzeugnisse | X37: 384635.18 | Z37: unfertige Erzeugnisse | AA37: 1085243
A38: Fertigwaren | B38: 21718789 | C38: 19669034 | D38: 18095511 | E38: 42.33 | G38: Fertigwaren | H38: 18626402 | I38: 13818892 | J38: =I38*0.92 -> 12713380 | K38: 18.74 | M38: Rohstoffe | N38: 4662107.8 | O38: -0.0074 | Q38: Halbfertigwaren | R38: 491496.5 | T38: Rohstoffe | U38: 4193418.5 | W38: fertige Erzeugnisse und Waren | X38: 9980752.6 | Z38: fertige Erzeugnisse und Waren | AA38: 7393942.2
A39: Halbfabrikate | B39: 268343.54 | C39: 130133.19 | D39: 1899060.8 | E39: 23.97 | G39: Halbfabrikate | H39: 429902.55 | I39: 290977.14 | J39: =I39+I40+I37 -> 1531899.2 | K39: -8.69 | M39: Verpackungen | N39: 8238119.3 | O39: -0.0062 | Q39: Monokroketten | R39: 403709.43 | T39: Verpackungen | U39: 8305827.7 | W39: Gesamt | X39: 22992000 | Z39: Gesamt | AA39: 19951495
A40: Monokroketten | B40: 1388053 | C40: 912188.47 | D40: bei Halbfabrikate | G40: Monokroketten | H40: 1006184.8 | I40: 568225.33 | J40: bei Halbfabrikate | M40: Werbeartikel | N40: 0 | O40: 0 | Q40: Motorenteile | R40: 0 | T40: Werkstatt | U40: 28667.55
A41: Rohstoffe | B41: 9796291.6 | C41: 8032887.8 | D41: 8032887.8 | E41: 32.89 | G41: Rohstoffe | H41: 6190242.4 | I41: 6044896.1 | J41: =I41 -> 6044896.1 | K41: 29.66 | M41: Gesamt | N41: 25284608 | O41: -0.0032 | Q41: Rohstoffe | R41: 4696738.7 | T41: Gas Heizöl Diesel AdBlue | U41: 15617.93
A42: Verpackungen | B42: 2500524.1 | C42: 11373810 | D42: 11373810 | E42: 14.28 | G42: Verpackungen | H42: 3058856.2 | I42: 9952404.6 | J42: =I42 -> 9952404.6 | K42: 20.81 | Q42: Verpackungen | R42: 8289649.2 | T42: Gesamt | U42: 23462207
A43: Werbeartikel | B43: 98491.951 | C43: 0 | D43: 0 | G43: Werbeartikel | H43: 122574.06 | I43: 0 | J43: 0 | K43: 0 | M43: Anmerkung für 2019 | Q43: Werbeartikel | R43: 0
A44: Gesamtergebnis | B44: 36920972 | C44: 40974792 | D44: =SUM(D36:D43) -> 39401269 | E44: 30.28 | G44: Gesamtergebnis | H44: =SUM(H36:H43) -> 30244627 | I44: =SUM(I36:I43) -> 31348092 | J44: =SUM(J36:J43) -> 30242580 | K44: 19.61 | M44: Bei der FW wurde Verpackungsschwund und Mischkosten, reduzierte Palettenpreise | Q44: Gesamt | R44: 25365400
M45: mit 8% in Abzug gebracht
A46: Anmerkung für 2021 | G46: Anmerkung für 2020 | Q46: Anmerkung für 2018:
A47: Bei der FW wurde Verpackungsschwund und Mischkosten, reduzierte Palettenpreise | G47: Bei der FW wurde Verpackungsschwund und Mischkosten, reduzierte Palettenpreise | Q47: Bei der FW wurde Verpackungsschwund und Mischkosten, reduzierte Palettenpreise mit 8% in Abzug gebracht.
...
